Workbook
Name Slicer_Diabetes_Status: #N/A
Name Slicer_Weight_Status: #N/A

Sheet Customer Names
A1: Customer ID | B1: name
A2: Id1 | B2: Hawks, Ms. Kelly
A3: Id2 | B3: Lehner, Mr. Matthew D
A4: Id3 | B4: Lu, Mr. Phil
A5: Id4 | B5: Osborne, Ms. Kelsey
A6: Id5 | B6: Kadala, Ms. Kristyn
A7: Id6 | B7: Baker, Mr. Russell B.
A8: Id7 | B8: Macpherson, Mr. Scott
A9: Id8 | B9: Hallman, Mr. Stephen
A10: Id9 | B10: Moran, Mr. Patrick R.
A11: Id10 | B11: Benner, Ms. Brooke N.
A12: Id11 | B12: Fierro Vargas, Ms. Paola Andrea
... A2336: Id2335 | B2336: German, Mr. Aaron K

Sheet Medical Examinations
A1: Customer ID | B1: BMI | C1: HBA1C | D1: Heart Issues | E1: Any Transplants | F1: Cancer history | G1: NumberOfMajorSurgeries | H1: smoker
A2: Id1 | B2: 47.41 | C2: 7.47 | D2: No | E2: No | F2: No | G2: No major surgery | H2: yes
A3: Id2 | B3: 30.36 | C3: 5.77 | D3: No | E3: No | F3: No | G3: No major surgery | H3: yes
A4: Id3 | B4: 34.485 | C4: 11.87 | D4: yes | E4: No | F4: No | G4: 2 | H4: yes
A5: Id4 | B5: 38.095 | C5: 6.05 | D5: No | E5: No | F5: No | G5: No major surgery | H5: yes
A6: Id5 | B6: 35.53 | C6: 5.45 | D6: No | E6: No | F6: No | G6: No major surgery | H6: yes
A7: Id6 | B7: 32.8 | C7: 6.59 | D7: No | E7: No | F7: No | G7: No major surgery | H7: yes
A8: Id7 | B8: 36.4 | C8: 6.07 | D8: No | E8: No | F8: No | G8: No major surgery | H8: yes
A9: Id8 | B9: 36.96 | C9: 7.93 | D9: No | E9: No | F9: No | G9: 3 | H9: yes
A10: Id9 | B10: 41.14 | C10: 9.58 | D10: yes | E10: No | F10: Yes | G10: 1 | H10: yes
A11: Id10 | B11: 38.06 | C11: 10.79 | D11: No | E11: No | F11: No | G11: No major surgery | H11: yes
A12: Id11 | B12: 37.7 | C12: 5.96 | D12: yes | E12: No | F12: No | G12: 2 | H12: yes
A13: Id12 | B13: 42.13 | C13: 11.9 | D13: No | E13: No | F13: No | G13: No major surgery | H13: yes
A14: Id13 | B14: 40.92 | C14: 8.41 | D14: No | E14: No | F14: No | G14: No major surgery | H14: yes
A15: Id14 | B15: 40.565 | C15: 7.02 | D15: No | E15: No | F15: No | G15: No major surgery | H15: yes
A16: Id15 | B16: 36.385 | C16: 7.59 | D16: yes | E16: No | F16: No | G16: 2 | H16: yes
A17: Id16 | B17: 39.9 | C17: 11.32 | D17: No | E17: No | F17: No | G17: No major surgery | H17: yes
A18: Id17 | B18: 33.8 | C18: 7.67 | D18: No | E18: No | F18: No | G18: 3 | H18: yes
A19: Id18 | B19: 36.765 | C19: 7.29 | D19: yes | E19: No | F19: Yes | G19: 1 | H19: yes
A20: Id19 | B20: 36.955 | C20: 4.72 | D20: yes | E20: No | F20: No | G20: 1 | H20: yes
A21: Id20 | B21: 42.9 | C21: 11.41 | D21: No | E21: No | F21: No | G21: No major surgery | H21: yes
A22: Id21 | B22: 36.3 | C22: 11.5 | D22: yes | E22: No | F22: No | G22: 2 | H22: yes
A23: Id22 | B23: 32.2 | C23: 6.22 | D23: yes | E23: No | F23: No | G23: 2 | H23: yes
A24: Id23 | B24: 31.3 | C24: 11.38 | D24: No | E24: No | F24: No | G24: 3 | H24: yes
A25: Id24 | B25: 41.8 | C25: 7.89 | D25: yes | E25: No | F25: No | G25: 2 | H25: yes
A26: Id25 | B26: 35.09 | C26: 4.38 | D26: yes | E26: No | F26: No | G26: 2 | H26: yes
A27: Id26 | B27: 33.88 | C27: 7.01 | D27: No | E27: No | F27: No | G27: 3 | H27: yes
A28: Id27 | B28: 30.875 | C28: 11.88 | D28: No | E28: No | F28: No | G28: No major surgery | H28: yes
A29: Id28 | B29: 36.86 | C29: 5.19 | D29: yes | E29: No | F29: Yes | G29: 1 | H29: yes
A30: Id29 | B30: 35.86 | C30: 6.74 | D30: yes | E30: No | F30: No | G30: 2 | H30: yes
A31: Id30 | B31: 37.05 | C31: 8.44 | D31: No | E31: No | F31: No | G31: No major surgery | H31: yes
A32: Id31 | B32: 43.89 | C32: 8.71 | D32: No | E32: No | F32: No | G32: No major surgery | H32: yes
A33: Id32 | B33: 42.35 | C33: 5.08 | D33: yes | E33: No | F33: No | G33: No major surgery | H33: yes
A34: Id33 | B34: 31.35 | C34: 6.86 | D34: No | E34: No | F34: No | G34: No major surgery | H34: yes
A35: Id34 | B35: 47.6 | C35: 5.95 | D35: yes | E35: No | F35: No | G35: No major surgery | H35: yes
A36: Id35 | B36: 46.2 | C36: 6.09 | D36: No | E36: No | F36: Yes | G36: 1 | H36: yes
A37: Id36 | B37: 32.015 | C37: 11.75 | D37: No | E37: No | F37: No | G37: No major surgery | H37: yes
A38: Id37 | B38: 40.565 | C38: 7.37 | D38: No | E38: No | F38: No | G38: No major surgery | H38: yes
A39: Id38 | B39: 32.45 | C39: 11.91 | D39: No | E39: No | F39: No | G39: No major surgery | H39: yes
A40: Id39 | B40: 34.96 | C40: 6.52 | D40: No | E40: No | F40: No | G40: No major surgery | H40: yes
...

Sheet Hospitalisation Details
A1: Customer ID | B1: year | C1: month | D1: date | E1: children | F1: charges | G1: Hospital tier | H1: City tier | I1: State ID
A2: Id2335 | B2: 1992 | C2: Jul | D2: 9 | E2: 0 | F2: 563.84 | G2: tier - 2 | H2: tier - 3 | I2: R1013
A3: Id2334 | B3: 1992 | C3: Nov | D3: 30 | E3: 0 | F3: 570.62 | G3: tier - 2 | H3: tier - 1 | I3: R1013
A4: Id2333 | B4: 1993 | C4: Jun | D4: 30 | E4: 0 | F4: 600 | G4: tier - 2 | H4: tier - 1 | I4: R1013
A5: Id2332 | B5: 1992 | C5: Sep | D5: 13 | E5: 0 | F5: 604.54 | G5: tier - 3 | H5: tier - 3 | I5: R1013
A6: Id2331 | B6: 1998 | C6: Jul | D6: 27 | E6: 0 | F6: 637.26 | G6: tier - 3 | H6: tier - 3 | I6: R1013
A7: Id2330 | B7: 2001 | C7: Nov | D7: 20 | E7: 0 | F7: 646.14 | G7: tier - 3 | H7: tier - 3 | I7: R1012
A8: Id2329 | B8: 1993 | C8: Jun | D8: 1 | E8: 0 | F8: 650 | G8: tier - 3 | H8: tier - 3 | I8: R1013
A9: Id2328 | B9: 1995 | C9: Jul | D9: 4 | E9: 0 | F9: 650 | G9: tier - 3 | H9: tier - 3 | I9: R1013
A10: Id2327 | B10: 2002 | C10: Nov | D10: 29 | E10: 0 | F10: 668 | G10: tier - 3 | H10: tier - 2 | I10: R1012
A11: Id2326 | B11: 1997 | C11: Nov | D11: 9 | E11: 0 | F11: 670 | G11: tier - 3 | H11: tier - 3 | I11: R1013
A12: Id2325 | B12: 2001 | C12: Sep | D12: 12 | E12: 0 | F12: 687.54 | G12: tier - 3 | H12: tier - 2 | I12: R1013
A13: Id2324 | B13: 1999 | C13: Dec | D13: 26 | E13: 0 | F13: 700 | G13: ? | H13: tier - 3 | I13: R1013
... A1050: Id1290 | B1050: 1977 | C1050: Jul | D1050: 26 | E1050: 2 | F1050: 8527.53 | G1050: tier - 2 | H1050: tier - 2 | I1050: R1013
A1051: Id1289 | B1051: ? | C1051: Jul | D1051: 24 | E1051: 0 | F1051: 8534.67 | G1051: tier - 2 | H1051: tier - 3 | I1051: R1024
A1052: Id1288 | B1052: 1981 | C1052: Dec | D1052: 27 | E1052: 3 | F1052: 8538.29 | G1052: tier - 2 | H1052: tier - 3 | I1052: R1024
A1053: Id1287 | B1053: 1975 | C1053: Nov | D1053: 6 | E1053: 1 | F1053: 8539.67 | G1053: tier - 2 | H1053: tier - 3 | I1053: R1011
A1054: Id1286 | B1054: ? | C1054: Dec | D1054: 12 | E1054: 1 | F1054: 8547.69 | G1054: tier - 2 | H1054: tier - 1 | I1054: R1013
A1055: Id1285 | B1055: 1975 | C1055: Aug | D1055: 6 | E1055: 1 | F1055: 8551.35 | G1055: tier - 2 | H1055: tier - 2 | I1055: R1011
A1056: Id1284 | B1056: 1975 | C1056: Aug | D1056: 21 | E1056: 1 | F1056: 8556.91 | G1056: tier - 2 | H1056: tier - 1 | I1056: R1011
A1057: Id1283 | B1057: 1988 | C1057: Sep | D1057: 21 | E1057: 3 | F1057: 8567.25 | G1057: tier - 2 | H1057: tier - 1 | I1057: R1012
A1058: Id1282 | B1058: 1975 | C1058: Sep | D1058: 26 | E1058: 1 | F1058: 8569.86 | G1058: tier - 2 | H1058: tier - 3 | I1058: R1013
A1059: Id1281 | B1059: 1982 | C1059: Dec | D1059: 6 | E1059: 3 | F1059: 8572.04 | G1059: tier - 2 | H1059: tier - 2 | I1059: R1021
A1060: Id1280 | B1060: 1987 | C1060: Nov | D1060: 11 | E1060: 3 | F1060: 8573.3 | G1060: tier - 2 | H1060: tier - 2 | I1060: R1021
A1061: Id1279 | B1061: 1983 | C1061: Dec | D1061: 30 | E1061: 5 | F1061: 8582.3 | G1061: tier - 2 | H1061: tier - 1 | I1061: R1013
A1062: Id1278 | B1062: 1983 | C1062: Jul | D1062: 25 | E1062: 5 | F1062: 8596.83 | G1062: tier - 2 | H1062: tier - 3 | I1062: R1013
A1063: Id1277 | B1063: 1973 | C1063: Jul | D1063: 11 | E1063: 0 | F1063: 8601.33 | G1063: tier - 2 | H1063: tier - 1 | I1063: R1013
A1064: Id1276 | B1064: 1977 | C1064: Sep | D1064: 24 | E1064: 2 | F1064: 8603.82 | G1064: tier - 2 | H1064: tier - 1 | I1064: R1019
A1065: Id1275 | B1065: 1977 | C1065: Nov | D1065: 12 | E1065: 2 | F1065: 8604.48 | G1065: tier - 3 | H1065: tier - 2 | I1065: R1016
A1066: Id1274 | B1066: 1977 | C1066: Oct | D1066: 15 | E1066: 3 | F1066: 8605.36 | G1066: tier - 2 | H1066: tier - 2 | I1066: R1013
... A2344: Id1 | B2344: 1968 | C2344: Oct | D2344: 12 | E2344: 0 | F2344: 63770.43 | G2344: tier - 1 | H2344: tier - 3 | I2344: R1013

Sheet Customer Names-Answers
A1: Customer ID | B1: name | C1: Title | D1: First Name | E1: Last Name
A2: Id1 | B2: Hawks, Ms. Kelly | C2: =MID(B2,SEARCH(", ",B2),5) -> , Ms. | D2: Kelly | E2: Hawks
A3: Id2 | B3: Lehner, Mr. Matthew D | C3: =MID(B3,SEARCH(", ",B3),5) -> , Mr. | D3: Matthew D | E3: Lehner
A4: Id3 | B4: Lu, Mr. Phil | C4: =MID(B4,SEARCH(", ",B4),5) -> , Mr. | D4: Phil | E4: Lu
A5: Id4 | B5: Osborne, Ms. Kelsey | C5: =MID(B5,SEARCH(", ",B5),5) -> , Ms. | D5: Kelsey | E5: Osborne
A6: Id5 | B6: Kadala, Ms. Kristyn | C6: =MID(B6,SEARCH(", ",B6),5) -> , Ms. | D6: Kristyn | E6: Kadala
A7: Id6 | B7: Baker, Mr. Russell B. | C7: =MID(B7,SEARCH(", ",B7),5) -> , Mr. | D7: Russell B. | E7: Baker
A8: Id7 | B8: Macpherson, Mr. Scott | C8: =MID(B8,SEARCH(", ",B8),5) -> , Mr. | D8: Scott | E8: Macpherson
A9: Id8 | B9: Hallman, Mr. Stephen | C9: =MID(B9,SEARCH(", ",B9),5) -> , Mr. | D9: Stephen | E9: Hallman
A10: Id9 | B10: Moran, Mr. Patrick R. | C10: =MID(B10,SEARCH(", ",B10),5) -> , Mr. | D10: Patrick R. | E10: Moran
A11: Id10 | B11: Benner, Ms. Brooke N. | C11: =MID(B11,SEARCH(", ",B11),5) -> , Ms. | D11: Brooke N. | E11: Benner
A12: Id11 | B12: Fierro Vargas, Ms. Paola Andrea | C12: =MID(B12,SEARCH(", ",B12),5) -> , Ms. | D12: Ms. Paola Andrea | E12: Fierro Vargas
A13: Id12 | B13: Franz, Mr. David | C13: =MID(B13,SEARCH(", ",B13),5) -> , Mr. | D13: David | E13: Franz
... A2336: Id2335 | B2336: German, Mr. Aaron K | C2336: =MID(B2336,SEARCH(", ",B2336),5) -> , Mr. | D2336: Aaron K | E2336: German

Sheet Medical Examinations-Answers
A1: 1 | B1: =A1+1 -> 2 | C1: =B1+1 -> 3 | D1: =C1+1 -> 4 | E1: =D1+1 -> 5 | F1: =E1+1 -> 6 | G1: =F1+1 -> 7 | H1: =G1+1 -> 8 | I1: =H1+1 -> 9 | J1: =I1+1 -> 10
A2: Customer ID | B2: BMI | C2: HBA1C | D2: Heart Issues | E2: Any Transplants | F2: Cancer history | G2: NumberOfMajorSurgeries | H2: smoker | I2: Weight Status | J2: Diabetes Status
A3: Id1 | B3: 47.41 | C3: 7.47 | D3: No | E3: No | F3: No | G3: 0 | H3: yes | I3: {=_xlfn.IFS(B3>=30,"Obesity",AND(B3>=25,B3<=29.99),"Overweight ",AND(B3>=18.5,B3<=24.99),"Normal Weight ",B3<18.5,"Underweight ")} -> Obesity | J3: {=_xlfn.IFS($C3>=6.5,"Diabetes",AND($C3>=5.7,$C3<=6.5),"Prediabetes",$C3<5.7,"Normal")} -> Diabetes
A4: Id2 | B4: 30.36 | C4: 5.77 | D4: No | E4: No | F4: No | G4: 0 | H4: yes | I4: {=_xlfn.IFS(B4>=30,"Obesity",AND(B4>=25,B4<=29.99),"Overweight ",AND(B4>=18.5,B4<=24.99),"Normal Weight ",B4<18.5,"Underweight ")} -> Obesity | J4: {=_xlfn.IFS($C4>=6.5,"Diabetes",AND($C4>=5.7,$C4<=6.5),"Prediabetes",$C4<5.7,"Normal")} -> Prediabetes
A5: Id3 | B5: 34.485 | C5: 11.87 | D5: yes | E5: No | F5: No | G5: 2 | H5: yes | I5: {=_xlfn.IFS(B5>=30,"Obesity",AND(B5>=25,B5<=29.99),"Overweight ",AND(B5>=18.5,B5<=24.99),"Normal Weight ",B5<18.5,"Underweight ")} -> Obesity | J5: {=_xlfn.IFS($C5>=6.5,"Diabetes",AND($C5>=5.7,$C5<=6.5),"Prediabetes",$C5<5.7,"Normal")} -> Diabetes
A6: Id4 | B6: 38.095 | C6: 6.05 | D6: No | E6: No | F6: No | G6: 0 | H6: yes | I6: {=_xlfn.IFS(B6>=30,"Obesity",AND(B6>=25,B6<=29.99),"Overweight ",AND(B6>=18.5,B6<=24.99),"Normal Weight ",B6<18.5,"Underweight ")} -> Obesity | J6: {=_xlfn.IFS($C6>=6.5,"Diabetes",AND($C6>=5.7,$C6<=6.5),"Prediabetes",$C6<5.7,"Normal")} -> Prediabetes
A7: Id5 | B7: 35.53 | C7: 5.45 | D7: No | E7: No | F7: No | G7: 0 | H7: yes | I7: {=_xlfn.IFS(B7>=30,"Obesity",AND(B7>=25,B7<=29.99),"Overweight ",AND(B7>=18.5,B7<=24.99),"Normal Weight ",B7<18.5,"Underweight ")} -> Obesity | J7: {=_xlfn.IFS($C7>=6.5,"Diabetes",AND($C7>=5.7,$C7<=6.5),"Prediabetes",$C7<5.7,"Normal")} -> Normal
A8: Id6 | B8: 32.8 | C8: 6.59 | D8: No | E8: No | F8: No | G8: 0 | H8: yes | I8: {=_xlfn.IFS(B8>=30,"Obesity",AND(B8>=25,B8<=29.99),"Overweight ",AND(B8>=18.5,B8<=24.99),"Normal Weight ",B8<18.5,"Underweight ")} -> Obesity | J8: {=_xlfn.IFS($C8>=6.5,"Diabetes",AND($C8>=5.7,$C8<=6.5),"Prediabetes",$C8<5.7,"Normal")} -> Diabetes
A9: Id7 | B9: 36.4 | C9: 6.07 | D9: No | E9: No | F9: No | G9: 0 | H9: yes | I9: {=_xlfn.IFS(B9>=30,"Obesity",AND(B9>=25,B9<=29.99),"Overweight ",AND(B9>=18.5,B9<=24.99),"Normal Weight ",B9<18.5,"Underweight ")} -> Obesity | J9: {=_xlfn.IFS($C9>=6.5,"Diabetes",AND($C9>=5.7,$C9<=6.5),"Prediabetes",$C9<5.7,"Normal")} -> Prediabetes
A10: Id8 | B10: 36.96 | C10: 7.93 | D10: No | E10: No | F10: No | G10: 3 | H10: yes | I10: {=_xlfn.IFS(B10>=30,"Obesity",AND(B10>=25,B10<=29.99),"Overweight ",AND(B10>=18.5,B10<=24.99),"Normal Weight ",B10<18.5,"Underweight ")} -> Obesity | J10: {=_xlfn.IFS($C10>=6.5,"Diabetes",AND($C10>=5.7,$C10<=6.5),"Prediabetes",$C10<5.7,"Normal")} -> Diabetes
A11: Id9 | B11: 41.14 | C11: 9.58 | D11: yes | E11: No | F11: Yes | G11: 1 | H11: yes | I11: {=_xlfn.IFS(B11>=30,"Obesity",AND(B11>=25,B11<=29.99),"Overweight ",AND(B11>=18.5,B11<=24.99),"Normal Weight ",B11<18.5,"Underweight ")} -> Obesity | J11: {=_xlfn.IFS($C11>=6.5,"Diabetes",AND($C11>=5.7,$C11<=6.5),"Prediabetes",$C11<5.7,"Normal")} -> Diabetes
A12: Id10 | B12: 38.06 | C12: 10.79 | D12: No | E12: No | F12: No | G12: 0 | H12: yes | I12: {=_xlfn.IFS(B12>=30,"Obesity",AND(B12>=25,B12<=29.99),"Overweight ",AND(B12>=18.5,B12<=24.99),"Normal Weight ",B12<18.5,"Underweight ")} -> Obesity | J12: {=_xlfn.IFS($C12>=6.5,"Diabetes",AND($C12>=5.7,$C12<=6.5),"Prediabetes",$C12<5.7,"Normal")} -> Diabetes
A13: Id11 | B13: 37.7 | C13: 5.96 | D13: yes | E13: No | F13: No | G13: 2 | H13: yes | I13: {=_xlfn.IFS(B13>=30,"Obesity",AND(B13>=25,B13<=29.99),"Overweight ",AND(B13>=18.5,B13<=24.99),"Normal Weight ",B13<18.5,"Underweight ")} -> Obesity | J13: {=_xlfn.IFS($C13>=6.5,"Diabetes",AND($C13>=5.7,$C13<=6.5),"Prediabetes",$C13<5.7,"Normal")} -> Prediabetes
A14: Id12 | B14: 42.13 | C14: 11.9 | D14: No | E14: No | F14: No | G14: 0 | H14: yes | I14: {=_xlfn.IFS(B14>=30,"Obesity",AND(B14>=25,B14<=29.99),"Overweight ",AND(B14>=18.5,B14<=24.99),"Normal Weight ",B14<18.5,"Underweight ")} -> Obesity | J14: {=_xlfn.IFS($C14>=6.5,"Diabetes",AND($C14>=5.7,$C14<=6.5),"Prediabetes",$C14<5.7,"Normal")} -> Diabetes
... A2337: Id2335 | B2337: 17.58 | C2337: 4.51 | D2337: No | E2337: No | F2337: No | G2337: 1 | H2337: No | I2337: {=_xlfn.IFS(B2337>=30,"Obesity",AND(B2337>=25,B2337<=29.99),"Overweight ",AND(B2337>=18.5,B2337<=24.99),"Normal Weight ",B2337<18.5,"Underweight ")} -> Underweight | J2337: {=_xlfn.IFS($C2337>=6.5,"Diabetes",AND($C2337>=5.7,$C2337<=6.5),"Prediabetes",$C2337<5.7,"Normal")} -> Normal
B2338: 29.9 | I2338: {=_xlfn.IFS(B2338>=30,"Obesity",AND(B2338>=25,B2338<=29.99),"Overweight ",AND(B2338>=18.5,B2338<=24.99),"Normal Weight ",B2338<18.5,"Underweight ")} -> Overweight | J2338: {=_xlfn.IFS($C2338>=6.5,"Diabetes",AND($C2338>=5.7,$C2338<=6.5),"Prediabetes",$C2338<5.7,"Normal")} -> Normal

Sheet Hospitalisation Details-Answers
A1: 1 | B1: =A1+1 -> 2 | C1: =B1+1 -> 3 | D1: =C1+1 -> 4 | E1: =D1+1 -> 5 | F1: =E1+1 -> 6 | G1: =F1+1 -> 7 | H1: =G1+1 -> 8 | I1: =H1+1 -> 9 | ... K1: =J1+1 -> 11
A2: Customer ID | B2: year | C2: month | D2: date | E2: children | F2: charges | G2: Hospital tier | H2: City tier | I2: State ID | J2: Date of Birth | K2: Age as on '8-June-2023' | L2: 45085
A3: Id2335 | B3: 1992 | C3: Jul | D3: 9 | E3: 0 | F3: 563.84 | G3: tier - 2 | H3: tier - 3 | I3: R1013 | J3: =_xlfn.CONCAT(D3,"-",C3,"-",B3) -> 9-Jul-1992 | K3: =YEAR($L$2)-YEAR(J3)&" Y " -> 31 Y
A4: Id2334 | B4: 1992 | C4: Nov | D4: 30 | E4: 0 | F4: 570.62 | G4: tier - 2 | H4: tier - 1 | I4: R1013 | J4: =_xlfn.CONCAT(D4,"-",C4,"-",B4) -> 30-Nov-1992 | K4: =YEAR($L$2)-YEAR(J4)&" Y " -> 31 Y
A5: Id2333 | B5: 1993 | C5: Jun | D5: 30 | E5: 0 | F5: 600 | G5: tier - 2 | H5: tier - 1 | I5: R1013 | J5: =_xlfn.CONCAT(D5,"-",C5,"-",B5) -> 30-Jun-1993 | K5: =YEAR($L$2)-YEAR(J5)&" Y " -> 30 Y
A6: Id2332 | B6: 1992 | C6: Sep | D6: 13 | E6: 0 | F6: 604.54 | G6: tier - 3 | H6: tier - 3 | I6: R1013 | J6: =_xlfn.CONCAT(D6,"-",C6,"-",B6) -> 13-Sep-1992 | K6: =YEAR($L$2)-YEAR(J6)&" Y " -> 31 Y
A7: Id2331 | B7: 1998 | C7: Jul | D7: 27 | E7: 0 | F7: 637.26 | G7: tier - 3 | H7: tier - 3 | I7: R1013 | J7: =_xlfn.CONCAT(D7,"-",C7,"-",B7) -> 27-Jul-1998 | K7: =YEAR($L$2)-YEAR(J7)&" Y " -> 25 Y
A8: Id2330 | B8: 2001 | C8: Nov | D8: 20 | E8: 0 | F8: 646.14 | G8: tier - 3 | H8: tier - 3 | I8: R1012 | J8: =_xlfn.CONCAT(D8,"-",C8,"-",B8) -> 20-Nov-2001 | K8: =YEAR($L$2)-YEAR(J8)&" Y " -> 22 Y
A9: Id2329 | B9: 1993 | C9: Jun | D9: 1 | E9: 0 | F9: 650 | G9: tier - 3 | H9: tier - 3 | I9: R1013 | J9: =_xlfn.CONCAT(D9,"-",C9,"-",B9) -> 1-Jun-1993 | K9: =YEAR($L$2)-YEAR(J9)&" Y " -> 30 Y
A10: Id2328 | B10: 1995 | C10: Jul | D10: 4 | E10: 0 | F10: 650 | G10: tier - 3 | H10: tier - 3 | I10: R1013 | J10: =_xlfn.CONCAT(D10,"-",C10,"-",B10) -> 4-Jul-1995 | K10: =YEAR($L$2)-YEAR(J10)&" Y " -> 28 Y
A11: Id2327 | B11: 2002 | C11: Nov | D11: 29 | E11: 0 | F11: 668 | G11: tier - 3 | H11: tier - 2 | I11: R1012 | J11: =_xlfn.CONCAT(D11,"-",C11,"-",B11) -> 29-Nov-2002 | K11: =YEAR($L$2)-YEAR(J11)&" Y " -> 21 Y
A12: Id2326 | B12: 1997 | C12: Nov | D12: 9 | E12: 0 | F12: 670 | G12: tier - 3 | H12: tier - 3 | I12: R1013 | J12: =_xlfn.CONCAT(D12,"-",C12,"-",B12) -> 9-Nov-1997 | K12: =YEAR($L$2)-YEAR(J12)&" Y " -> 26 Y
A13: Id2325 | B13: 2001 | C13: Sep | D13: 12 | E13: 0 | F13: 687.54 | G13: tier - 3 | H13: tier - 2 | I13: R1013 | J13: =_xlfn.CONCAT(D13,"-",C13,"-",B13) -> 12-Sep-2001 | K13: =YEAR($L$2)-YEAR(J13)&" Y " -> 22 Y
A14: Id2324 | B14: 1999 | C14: Dec | D14: 26 | E14: 0 | F14: 700 | G14: tier - 2 | H14: tier - 3 | I14: R1013 | J14: =_xlfn.CONCAT(D14,"-",C14,"-",B14) -> 26-Dec-1999 | K14: =YEAR($L$2)-YEAR(J14)&" Y " -> 24 Y
... A2345: Id1 | B2345: 1968 | C2345: Oct | D2345: 12 | E2345: 0 | F2345: 63770.43 | G2345: tier - 1 | H2345: tier - 3 | I2345: R1013 | J2345: =_xlfn.CONCAT(D2345,"-",C2345,"-",B2345) -> 12-Oct-1968 | K2345: =YEAR($L$2)-YEAR(J2345)&" Y " -> 55 Y

Sheet Healthcare
A1: Customer ID | B1: First Name | C1: charges | D1: Hospital tier | E1: City tier | F1: State ID | G1: Date of Birth | H1: Age | I1: BMI | J1: HBA1C | K1: Heart Issues | L1: Any Transplants | M1: Cancer history | N1: NumberOfMajorSurgeries | O1: smoker | P1: Weight Status | Q1: Diabetes Status | R1: Transplant Category
A2: Id1 | B2: =VLOOKUP(A2,'Customer Names-Answers'!A:D,4,0) -> Kelly | C2: {=VLOOKUP(A2,'Hospitalisation Details-Answers'!A:K,{6,7,8,9,10,11},0)} -> 63770.43 | D2: tier - 1 | E2: tier - 3 | F2: R1013 | G2: 12-Oct-1968 | H2: 55 Y | I2: {=VLOOKUP(A2,'Medical Examinations-Answers'!A:J,{2,3,4,5,6,7,8,9,10},0)} -> 47.41 | J2: 7.47 | K2: No | L2: No | M2: No | N2: 0 | O2: yes | P2: Obesity | Q2: Diabetes | R2: =IF(L2="No","Without transplant","With transplant") -> Without transplant
A3: Id2 | B3: =VLOOKUP(A3,'Customer Names-Answers'!A:D,4,0) -> Matthew D | C3: {=VLOOKUP(A3,'Hospitalisation Details-Answers'!A:K,{6,7,8,9,10,11},0)} -> 62592.87 | D3: tier - 2 | E3: tier - 3 | F3: R1013 | G3: 8-Jun-1977 | H3: 46 Y | I3: {=VLOOKUP(A3,'Medical Examinations-Answers'!A:J,{2,3,4,5,6,7,8,9,10},0)} -> 30.36 | J3: 5.77 | K3: No | L3: No | M3: No | N3: 0 | O3: yes | P3: Obesity | Q3: Prediabetes | R3: =IF(L3="No","Without transplant","With transplant") -> Without transplant
A4: Id3 | B4: =VLOOKUP(A4,'Customer Names-Answers'!A:D,4,0) -> Phil | C4: {=VLOOKUP(A4,'Hospitalisation Details-Answers'!A:K,{6,7,8,9,10,11},0)} -> 60021.4 | D4: tier - 1 | E4: tier - 1 | F4: R1012 | G4: 11-Sep-1970 | H4: 53 Y | I4: {=VLOOKUP(A4,'Medical Examinations-Answers'!A:J,{2,3,4,5,6,7,8,9,10},0)} -> 34.485 | J4: 11.87 | K4: yes | L4: No | M4: No | N4: 2 | O4: yes | P4: Obesity | Q4: Diabetes | R4: =IF(L4="No","Without transplant","With transplant") -> Without transplant
A5: Id4 | B5: =VLOOKUP(A5,'Customer Names-Answers'!A:D,4,0) -> Kelsey | C5: {=VLOOKUP(A5,'Hospitalisation Details-Answers'!A:K,{6,7,8,9,10,11},0)} -> 58571.07 | D5: tier - 1 | E5: tier - 3 | F5: R1024 | G5: 6-Jun-1991 | H5: 32 Y | I5: {=VLOOKUP(A5,'Medical Examinations-Answers'!A:J,{2,3,4,5,6,7,8,9,10},0)} -> 38.095 | J5: 6.05 | K5: No | L5: No | M5: No | N5: 0 | O5: yes | P5: Obesity | Q5: Prediabetes | R5: =IF(L5="No","Without transplant","With transplant") -> Without transplant
A6: Id5 | B6: =VLOOKUP(A6,'Customer Names-Answers'!A:D,4,0) -> Kristyn | C6: {=VLOOKUP(A6,'Hospitalisation Details-Answers'!A:K,{6,7,8,9,10,11},0)} -> 55135.4 | D6: tier - 1 | E6: tier - 2 | F6: R1012 | G6: 19-Jun-1989 | H6: 34 Y | I6: {=VLOOKUP(A6,'Medical Examinations-Answers'!A:J,{2,3,4,5,6,7,8,9,10},0)} -> 35.53 | J6: 5.45 | K6: No | L6: No | M6: No | N6: 0 | O6: yes | P6: Obesity | Q6: Normal | R6: =IF(L6="No","Without transplant","With transplant") -> Without transplant
A7: Id6 | B7: =VLOOKUP(A7,'Customer Names-Answers'!A:D,4,0) -> Russell B. | C7: {=VLOOKUP(A7,'Hospitalisation Details-Answers'!A:K,{6,7,8,9,10,11},0)} -> 52590.83 | D7: tier - 1 | E7: tier - 3 | F7: R1011 | G7: 4-Aug-1962 | H7: 61 Y | I7: {=VLOOKUP(A7,'Medical Examinations-Answers'!A:J,{2,3,4,5,6,7,8,9,10},0)} -> 32.8 | J7: 6.59 | K7: No | L7: No | M7: No | N7: 0 | O7: yes | P7: Obesity | Q7: Diabetes | R7: =IF(L7="No","Without transplant","With transplant") -> Without transplant
A8: Id7 | B8: =VLOOKUP(A8,'Customer Names-Answers'!A:D,4,0) -> Scott | C8: {=VLOOKUP(A8,'Hospitalisation Details-Answers'!A:K,{6,7,8,9,10,11},0)} -> 51194.56 | D8: tier - 1 | E8: tier - 3 | F8: R1011 | G8: 27-Oct-1994 | H8: 29 Y | I8: {=VLOOKUP(A8,'Medical Examinations-Answers'!A:J,{2,3,4,5,6,7,8,9,10},0)} -> 36.4 | J8: 6.07 | K8: No | L8: No | M8: No | N8: 0 | O8: yes | P8: Obesity | Q8: Prediabetes | R8: =IF(L8="No","Without transplant","With transplant") -> Without transplant
A9: Id8 | B9: =VLOOKUP(A9,'Customer Names-Answers'!A:D,4,0) -> Stephen | C9: {=VLOOKUP(A9,'Hospitalisation Details-Answers'!A:K,{6,7,8,9,10,11},0)} -> 49577.66 | D9: tier - 2 | E9: tier - 2 | F9: R1013 | G9: 27-Jun-1958 | H9: 65 Y | I9: {=VLOOKUP(A9,'Medical Examinations-Answers'!A:J,{2,3,4,5,6,7,8,9,10},0)} -> 36.96 | J9: 7.93 | K9: No | L9: No | M9: No | N9: 3 | O9: yes | P9: Obesity | Q9: Diabetes | R9: =IF(L9="No","Without transplant","With transplant") -> Without transplant
A10: Id9 | B10: =VLOOKUP(A10,'Customer Names-Answers'!A:D,4,0) -> Patrick R. | C10: {=VLOOKUP(A10,'Hospitalisation Details-Answers'!A:K,{6,7,8,9,10,11},0)} -> 48970.25 | D10: tier - 1 | E10: tier - 2 | F10: R1013 | G10: 4-Sep-1963 | H10: 60 Y | I10: {=VLOOKUP(A10,'Medical Examinations-Answers'!A:J,{2,3,4,5,6,7,8,9,10},0)} -> 41.14 | J10: 9.58 | K10: yes | L10: No | M10: Yes | N10: 1 | O10: yes | P10: Obesity | Q10: Diabetes | R10: =IF(L10="No","Without transplant","With transplant") -> Without transplant
A11: Id10 | B11: =VLOOKUP(A11,'Customer Names-Answers'!A:D,4,0) -> Brooke N. | C11: {=VLOOKUP(A11,'Hospitalisation Details-Answers'!A:K,{6,7,8,9,10,11},0)} -> 48885.14 | D11: tier - 1 | E11: tier - 2 | F11: R1013 | G11: 29-Dec-1978 | H11: 45 Y | I11: {=VLOOKUP(A11,'Medical Examinations-Answers'!A:J,{2,3,4,5,6,7,8,9,10},0)} -> 38.06 | J11: 10.79 | K11: No | L11: No | M11: No | N11: 0 | O11: yes | P11: Obesity | Q11: Diabetes | R11: =IF(L11="No","Without transplant","With transplant") -> Without transplant
A12: Id11 | B12: =VLOOKUP(A12,'Customer Names-Answers'!A:D,4,0) -> Ms. Paola Andrea | C12: {=VLOOKUP(A12,'Hospitalisation Details-Answers'!A:K,{6,7,8,9,10,11},0)} -> 48824.45 | D12: tier - 2 | E12: tier - 1 | F12: R1011 | G12: 22-Jul-1959 | H12: 64 Y | I12: {=VLOOKUP(A12,'Medical Examinations-Answers'!A:J,{2,3,4,5,6,7,8,9,10},0)} -> 37.7 | J12: 5.96 | K12: yes | L12: No | M12: No | N12: 2 | O12: yes | P12: Obesity | Q12: Prediabetes | R12: =IF(L12="No","Without transplant","With transplant") -> Without transplant
A13: Id12 | B13: =VLOOKUP(A13,'Customer Names-Answers'!A:D,4,0) -> David | C13: {=VLOOKUP(A13,'Hospitalisation Details-Answers'!A:K,{6,7,8,9,10,11},0)} -> 48675.52 | D13: tier - 1 | E13: tier - 2 | F13: R1013 | G13: 27-Oct-1965 | H13: 58 Y | I13: {=VLOOKUP(A13,'Medical Examinations-Answers'!A:J,{2,3,4,5,6,7,8,9,10},0)} -> 42.13 | J13: 11.9 | K13: No | L13: No | M13: No | N13: 0 | O13: yes | P13: Obesity | Q13: Diabetes | R13: =IF(L13="No","Without transplant","With transplant") -> Without transplant
... A2336: Id2335 | B2336: =VLOOKUP(A2336,'Customer Names-Answers'!A:D,4,0) -> Aaron K | C2336: {=VLOOKUP(A2336,'Hospitalisation Details-Answers'!A:K,{6,7,8,9,10,11},0)} -> 563.84 | D2336: tier - 2 | E2336: tier - 3 | F2336: R1013 | G2336: 9-Jul-1992 | H2336: 31 Y | I2336: {=VLOOKUP(A2336,'Medical Examinations-Answers'!A:J,{2,3,4,5,6,7,8,9,10},0)} -> 17.58 | J2336: 4.51 | K2336: No | L2336: No | M2336: No | N2336: 1 | O2336: No | P2336: Underweight | Q2336: Normal | R2336: =IF(L2336="No","Without transplant","With transplant") -> Without transplant

Sheet Pivot
A3: Smokers category | B3: Count of Customer ID
A4: No | B4: 1847
A5: yes | B5: 488
A6: Grand Total | B6: 2335
A13: Transplant Category | B13: Total NumberOf MajorSurgeries | C13: Average of HBA1C
A14: With transplant | B14: 162 | C14: 5.1876389
A15: Without transplant | B15: 1417 | C15: 6.6704427
A16: Grand Total | B16: 1579 | C16: 6.5789979
A32: Sum of charges | B32: Column Labels
A33: weight statuses | B33: Diabetes | C33: Normal | D33: Prediabetes | E33: Grand Total
A34: Normal Weight | B34: 1730218.2 | C34: 1714717.2 | D34: 860354.71 | E34: 4305290.1
A35: Obesity | B35: 8184059.1 | C35: 8520712.9 | D35: 3638874.8 | E35: 20343647
A36: Overweight | B36: 2240235.2 | C36: 2437209 | D36: 1051697.5 | E36: 5729141.8
A37: Underweight | B37: 483792.72 | C37: 566702.46 | D37: 163784.7 | E37: 1214279.9
A38: Grand Total | B38: 12638305 | C38: 13239342 | D38: 5714711.8 | E38: 31592359
A47: Row Labels | B47: Average of charges
A48: R1011 | B48: 19466.246
A49: R1012 | B49: 12016.474
A50: R1013 | B50: 10514.94
A51: R1014 | B51: 13478.057
A52: R1015 | B52: 13948.61
A53: R1016 | B53: 13589.263
A54: R1017 | B54: 14806.108
A55: R1018 | B55: 13272.787
A56: R1019 | B56: 13633.143
A57: R1020 | B57: 9238.4983
A58: R1021 | B58: 8933.3781
A59: R1022 | B59: 10650.521
... A65: Grand Total | B65: 13529.918
A70: Row Labels | B70: Sum of BMI | C70: Sum of HBA1C
A71: 19 Y | B71: 3058.155 | C71: 504.11
A72: 20 Y | B72: 2509.49 | C72: 441.38
A73: 21 Y | B73: 1546.15 | C73: 523.9
A74: 22 Y | B74: 1469.64 | C74: 251.53
A75: 23 Y | B75: 1483.385 | C75: 242.91
A76: 24 Y | B76: 1574.165 | C76: 264.12
A77: 25 Y | B77: 1359.615 | C77: 243.02
A78: 26 Y | B78: 1672.11 | C78: 289.56
A79: 27 Y | B79: 1339.42 | C79: 224.53
A80: 28 Y | B80: 1592.03 | C80: 262.06
...

Sheet Dashboard
